const catchError = require('../utils/catch-error')
const createError = require('../utils/create-error')

exports.createOrder = catchError(async (req,res,next) => {
    
})
exports.updateProfile = catchError(async (req,res,next) => {

})

exports.deleteOrder = catchError( async (req,res,next) => {

})

exports.getMe = catchError (async (req,res,next) => {

})

exports.getOrder = catchError (async(req,res,next)=> {
    
})